Workbook

Sheet Patient_records
A1: Patient ID | B1: Name | C1: Age | D1: Gender | E1: City | F1: Appointment Date | G1: Dapartment Name | H1: Showed Up | I1: Department ID | J1: Head Doctor | K1: Bed Capacity | L1: Senior category
A2: A10001 | B2: Praveen | C2: 28 | D2: Male | E2: Hyderabad | F2: 46142 | G2: Cardiology | H2: Yes | I2: =VLOOKUP(G2,Department_info!$A$2:$B$6,2,FALSE) -> D001 | J2: =INDEX(Department_info!$D$2:$D$6,MATCH(Patient_records!G2,Department_info!$A$2:$A$6,0)) -> Dr. Rao | K2: =INDEX(Department_info!$E$2:$E$6,MATCH(Patient_records!G2,Department_info!$A$2:$A$6,0)) -> 50 | L2: =IF(C2>30,"Senior","Normal") -> Normal
A3: A10002 | B3: Dhanush | C3: 22 | D3: Male | E3: Hyderabad | F3: 46143 | G3: Emergency | H3: Yes | I3: =VLOOKUP(G3,Department_info!$A$2:$B$6,2,FALSE) -> D005 | J3: =INDEX(Department_info!$D$2:$D$6,MATCH(Patient_records!G3,Department_info!$A$2:$A$6,0)) -> Dr. Reddy | K3: =INDEX(Department_info!$E$2:$E$6,MATCH(Patient_records!G3,Department_info!$A$2:$A$6,0)) -> 70 | L3: =IF(C3>30,"Senior","Normal") -> Normal
A4: A10003 | B4: Harpreet | C4: 22 | D4: Male | E4: Hyderabad | F4: 46144 | G4: Neurology | H4: No | I4: =VLOOKUP(G4,Department_info!$A$2:$B$6,2,FALSE) -> D002 | J4: =INDEX(Department_info!$D$2:$D$6,MATCH(Patient_records!G4,Department_info!$A$2:$A$6,0)) -> Dr. Mehta | K4: =INDEX(Department_info!$E$2:$E$6,MATCH(Patient_records!G4,Department_info!$A$2:$A$6,0)) -> 40 | L4: =IF(C4>30,"Senior","Normal") -> Normal
A5: A10004 | B5: Sekhar | C5: 19 | D5: Male | E5: Hyderabad | F5: 46145 | G5: Pediatrics | H5: No | I5: =VLOOKUP(G5,Department_info!$A$2:$B$6,2,FALSE) -> D004 | J5: =INDEX(Department_info!$D$2:$D$6,MATCH(Patient_records!G5,Department_info!$A$2:$A$6,0)) -> Dr. Sharma | K5: =INDEX(Department_info!$E$2:$E$6,MATCH(Patient_records!G5,Department_info!$A$2:$A$6,0)) -> 35 | L5: =IF(C5>30,"Senior","Normal") -> Normal
A6: A10005 | B6: Rangayya | C6: 20 | D6: Male | E6: Gudivada | F6: 46146 | G6: Orthopedics | H6: Yes | I6: =VLOOKUP(G6,Department_info!$A$2:$B$6,2,FALSE) -> D003 | J6: =INDEX(Department_info!$D$2:$D$6,MATCH(Patient_records!G6,Department_info!$A$2:$A$6,0)) -> Dr. Kumar | K6: =INDEX(Department_info!$E$2:$E$6,MATCH(Patient_records!G6,Department_info!$A$2:$A$6,0)) -> 60 | L6: =IF(C6>30,"Senior","Normal") -> Normal
A7: A10006 | B7: Rangamma | C7: 18 | D7: Female | E7: Gudivada | F7: 46147 | G7: Cardiology | H7: Yes | I7: =VLOOKUP(G7,Department_info!$A$2:$B$6,2,FALSE) -> D001 | J7: =INDEX(Department_info!$D$2:$D$6,MATCH(Patient_records!G7,Department_info!$A$2:$A$6,0)) -> Dr. Rao | K7: =INDEX(Department_info!$E$2:$E$6,MATCH(Patient_records!G7,Department_info!$A$2:$A$6,0)) -> 50 | L7: =IF(C7>30,"Senior","Normal") -> Normal
A8: A10007 | B8: Mogalayya | C8: 25 | D8: Male | E8: Begumpet | F8: 46148 | G8: Neurology | H8: Yes | I8: =VLOOKUP(G8,Department_info!$A$2:$B$6,2,FALSE) -> D002 | J8: =INDEX(Department_info!$D$2:$D$6,MATCH(Patient_records!G8,Department_info!$A$2:$A$6,0)) -> Dr. Mehta | K8: =INDEX(Department_info!$E$2:$E$6,MATCH(Patient_records!G8,Department_info!$A$2:$A$6,0)) -> 40 | L8: =IF(C8>30,"Senior","Normal") -> Normal
A9: A10008 | B9: Jangayya | C9: 45 | D9: Male | E9: Amaravathi | F9: 46149 | G9: Cardiology | H9: Yes | I9: =VLOOKUP(G9,Department_info!$A$2:$B$6,2,FALSE) -> D001 | J9: =INDEX(Department_info!$D$2:$D$6,MATCH(Patient_records!G9,Department_info!$A$2:$A$6,0)) -> Dr. Rao | K9: =INDEX(Department_info!$E$2:$E$6,MATCH(Patient_records!G9,Department_info!$A$2:$A$6,0)) -> 50 | L9: =IF(C9>30,"Senior","Normal") -> Senior
A10: A10009 | B10: Madhu | C10: 22 | D10: Male | E10: Godavari | F10: 46150 | G10: Emergency | H10: Yes | I10: =VLOOKUP(G10,Department_info!$A$2:$B$6,2,FALSE) -> D005 | J10: =INDEX(Department_info!$D$2:$D$6,MATCH(Patient_records!G10,Department_info!$A$2:$A$6,0)) -> Dr. Reddy | K10: =INDEX(Department_info!$E$2:$E$6,MATCH(Patient_records!G10,Department_info!$A$2:$A$6,0)) -> 70 | L10: =IF(C10>30,"Senior","Normal") -> Normal
A11: A10010 | B11: Rudra | C11: 28 | D11: Male | E11: Konaseema | F11: 46151 | G11: Neurology | H11: Yes | I11: =VLOOKUP(G11,Department_info!$A$2:$B$6,2,FALSE) -> D002 | J11: =INDEX(Department_info!$D$2:$D$6,MATCH(Patient_records!G11,Department_info!$A$2:$A$6,0)) -> Dr. Mehta | K11: =INDEX(Department_info!$E$2:$E$6,MATCH(Patient_records!G11,Department_info!$A$2:$A$6,0)) -> 40 | L11: =IF(C11>30,"Senior","Normal") -> Normal
A12: A10011 | B12: Mehar | C12: 29 | D12: Female | E12: Malakpet | F12: 46152 | G12: Pediatrics | H12: Yes | I12: =VLOOKUP(G12,Department_info!$A$2:$B$6,2,FALSE) -> D004 | J12: =INDEX(Department_info!$D$2:$D$6,MATCH(Patient_records!G12,Department_info!$A$2:$A$6,0)) -> Dr. Sharma | K12: =INDEX(Department_info!$E$2:$E$6,MATCH(Patient_records!G12,Department_info!$A$2:$A$6,0)) -> 35 | L12: =IF(C12>30,"Senior","Normal") -> Normal
A13: A10012 | B13: mohan | C13: 34 | D13: Male | E13: Kondaput | F13: 46153 | G13: Orthopedics | H13: Yes | I13: =VLOOKUP(G13,Department_info!$A$2:$B$6,2,FALSE) -> D003 | J13: =INDEX(Department_info!$D$2:$D$6,MATCH(Patient_records!G13,Department_info!$A$2:$A$6,0)) -> Dr. Kumar | K13: =INDEX(Department_info!$E$2:$E$6,MATCH(Patient_records!G13,Department_info!$A$2:$A$6,0)) -> 60 | L13: =IF(C13>30,"Senior","Normal") -> Senior
... A31: A10030 | B31: Dinesh | C31: 22 | D31: Male | E31: Chennai | F31: 46171 | G31: Emergency | H31: Yes | I31: =VLOOKUP(G31,Department_info!$A$2:$B$6,2,FALSE) -> D005 | J31: =INDEX(Department_info!$D$2:$D$6,MATCH(Patient_records!G31,Department_info!$A$2:$A$6,0)) -> Dr. Reddy | K31: =INDEX(Department_info!$E$2:$E$6,MATCH(Patient_records!G31,Department_info!$A$2:$A$6,0)) -> 70 | L31: =IF(C31>30,"Senior","Normal") -> Normal

Sheet Department_info
A1: DepartmentName | B1: DepartmentID | C1: Floor | D1: Head Doctor | E1: Bed Capacity | F1: No of Patients per doctor | G1: Average Patient Age per department | H1: Bed occupency % | I1: Bed Occupency
A2: Cardiology | B2: D001 | C2: 2 | D2: Dr. Rao | E2: 50 | F2: =COUNTIF(Patient_records!$J$2:$J$31,Department_info!D2) -> 9 | G2: =AVERAGEIF(Patient_records!$G$2:$G$31,Department_info!A2,Patient_records!$C$2:$C$31) -> 28.666667 | H2: =COUNTIF(Patient_records!$G$2:$G$31,Department_info!A2) / Department_info!E2 -> 0.18 | I2: =IF(H2>0.8,"Over Capacity","Normal") -> Normal
A3: Neurology | B3: D002 | C3: 3 | D3: Dr. Mehta | E3: 40 | F3: =COUNTIF(Patient_records!$J$2:$J$31,Department_info!D3) -> 8 | G3: =AVERAGEIF(Patient_records!$G$2:$G$31,Department_info!A3,Patient_records!$C$2:$C$31) -> 27.25 | H3: =COUNTIF(Patient_records!$G$2:$G$31,Department_info!A3) / Department_info!E3 -> 0.2 | I3: =IF(H3>0.8,"Over Capacity","Normal") -> Normal
A4: Orthopedics | B4: D003 | C4: 1 | D4: Dr. Kumar | E4: 60 | F4: =COUNTIF(Patient_records!$J$2:$J$31,Department_info!D4) -> 4 | G4: =AVERAGEIF(Patient_records!$G$2:$G$31,Department_info!A4,Patient_records!$C$2:$C$31) -> 27 | H4: =COUNTIF(Patient_records!$G$2:$G$31,Department_info!A4) / Department_info!E4 -> 0.066666667 | I4: =IF(H4>0.8,"Over Capacity","Normal") -> Normal
A5: Pediatrics | B5: D004 | C5: 4 | D5: Dr. Sharma | E5: 35 | F5: =COUNTIF(Patient_records!$J$2:$J$31,Department_info!D5) -> 4 | G5: =AVERAGEIF(Patient_records!$G$2:$G$31,Department_info!A5,Patient_records!$C$2:$C$31) -> 25.25 | H5: =COUNTIF(Patient_records!$G$2:$G$31,Department_info!A5) / Department_info!E5 -> 0.11428571 | I5: =IF(H5>0.8,"Over Capacity","Normal") -> Normal
A6: Emergency | B6: D005 | C6: 0 | D6: Dr. Reddy | E6: 70 | F6: =COUNTIF(Patient_records!$J$2:$J$31,Department_info!D6) -> 5 | G6: =AVERAGEIF(Patient_records!$G$2:$G$31,Department_info!A6,Patient_records!$C$2:$C$31) -> 24 | H6: =COUNTIF(Patient_records!$G$2:$G$31,Department_info!A6) / Department_info!E6 -> 0.071428571 | I6: =IF(H6>0.8,"Over Capacity","Normal") -> Normal

Sheet Pivot_reports
A4: Departments | B4: Count of Patient ID | E4: Count of Patient ID | F4: Column Labels | J4: Count of Patient ID | K4: Column Labels | O4: Count of Patient ID | P4: Column Labels
A5: Cardiology | B5: 9 | E5: Departments | F5: No | G5: Yes | J5: Departments | K5: No | L5: Yes | O5: Departments | P5: Cardiology | Q5: Emergency | R5: Neurology | S5: Orthopedics | T5: Pediatrics
A6: Emergency | B6: 5 | E6: Cardiology | F6: 0.066666667 | G6: 0.23333333 | J6: Cardiology | K6: 0.066666667 | L6: 0.23333333 | O6: Amaravathi | P6: 1
A7: Neurology | B7: 8 | E7: Emergency | F7: 0 | G7: 0.16666667 | J7: Emergency | K7: 0 | L7: 0.16666667 | O7: Begumpet | R7: 1
A8: Orthopedics | B8: 4 | E8: Neurology | F8: 0.1 | G8: 0.16666667 | J8: Neurology | K8: 0.1 | L8: 0.16666667 | O8: Bengalore | P8: 1
A9: Pediatrics | B9: 4 | E9: Orthopedics | F9: 0 | G9: 0.13333333 | J9: Orthopedics | K9: 0 | L9: 0.13333333 | O9: Chennai | Q9: 1
A10: Grand Total | B10: 30 | E10: Pediatrics | F10: 0.1 | G10: 0.033333333 | J10: Pediatrics | K10: 0.1 | L10: 0.033333333 | O10: Godavari | Q10: 1 | S10: 1
E11: Grand Total | F11: 0.26666667 | G11: 0.73333333 | J11: Grand Total | K11: 0.26666667 | L11: 0.73333333 | O11: Gudivada | P11: 1 | S11: 1
O12: Hafeezpet | P12: 1
O13: High tech city | R13: 1
O14: Hyderabad | P14: 1 | Q14: 2 | R14: 2 | T14: 2
J15: Patient ID | K15: (All) | O15: Konaseema | R15: 1
O16: Kondapur | P16: 1 | T16: 1
A17: Departments | B17: Average of Age | E17: Months | F17: Count of Patient ID | J17: Departments | K17: Count of Patient ID | O17: Kondaput | S17: 1
A18: Cardiology | B18: 28.666667 | E18: May | F18: 29 | J18: Cardiology | K18: 9 | O18: Malakpet | S18: 1 | T18: 1
A19: Emergency | B19: 24 | E19: Apr | F19: 1 | J19: Neurology | K19: 8 | O19: Nalgonda | P19: 1
A20: Neurology | B20: 27.25 | E20: Grand Total | F20: 30 | J20: Emergency | K20: 5 | O20: Nandigama | Q20: 1 | R20: 1
A21: Orthopedics | B21: 27 | J21: Grand Total | K21: 22 | O21: Petrorius | R21: 1
A22: Pediatrics | B22: 25.25 | O22: Rajkot | R22: 1
A23: Grand Total | B23: 26.833333 | O23: Singareni | P23: 1
O24: Vizag | P24: 1
O25: Grand Total | P25: 9 | Q25: 5 | R25: 8 | S25: 4 | T25: 4
A29: Count of Patient ID | B29: Column Labels | J29: Departments | K29: Count of Senior category
A30: city | B30: No | C30: Yes | D30: Grand Total | J30: Cardiology | K30: 9
A31: Amaravathi | C31: 1 | D31: 1 | J31: Emergency | K31: 5
A32: Begumpet | C32: 1 | D32: 1 | J32: Neurology | K32: 8
A33: Bengalore | C33: 1 | D33: 1 | J33: Orthopedics | K33: 4
A34: Chennai | C34: 1 | D34: 1 | J34: Pediatrics | K34: 4
A35: Godavari | C35: 2 | D35: 2 | J35: Grand Total | K35: 30
A36: Gudivada | C36: 2 | D36: 2
A37: Hafeezpet | C37: 1 | D37: 1
A38: High tech city | C38: 1 | D38: 1
A39: Hyderabad | B39: 4 | C39: 3 | D39: 7
A40: Konaseema | C40: 1 | D40: 1
A41: Kondapur | B41: 2 | D41: 2
A42: Kondaput | C42: 1 | D42: 1
A43: Malakpet | C43: 2 | D43: 2
A44: Nalgonda | C44: 1 | D44: 1
A45: Nandigama | B45: 1 | C45: 1 | D45: 2
A46: Petrorius | C46: 1 | D46: 1
...
